Cause exception while process update id=722185056 by bot id=6842489166
IndexError: list index out of range
Traceback (most recent call last):
  File "/root/bot-bugalter/auto-reports-bot/venv/lib/python3.11/site-packages/aiogram/dispatcher/dispatcher.py", line 309, in _process_update
    response = await self.feed_update(bot, update, **kwargs)
               ^^^^^^^^^^^^^^^^^^^^^^^^^^^^^^^^^^^^^^^^^^^^^
  File "/root/bot-bugalter/auto-reports-bot/venv/lib/python3.11/site-packages/aiogram/dispatcher/dispatcher.py", line 158, in feed_update
    response = await self.update.wrap_outer_middleware(
               ^^^^^^^^^^^^^^^^^^^^^^^^^^^^^^^^^^^^^^^^
  File "/root/bot-bugalter/auto-reports-bot/venv/lib/python3.11/site-packages/aiogram/dispatcher/middlewares/error.py", line 25, in __call__
    return await handler(event, data)
           ^^^^^^^^^^^^^^^^^^^^^^^^^^
  File "/root/bot-bugalter/auto-reports-bot/venv/lib/python3.11/site-packages/aiogram/dispatcher/middlewares/user_context.py", line 27, in __call__
    return await handler(event, data)
           ^^^^^^^^^^^^^^^^^^^^^^^^^^
  File "/root/bot-bugalter/auto-reports-bot/venv/lib/python3.11/site-packages/aiogram/fsm/middleware.py", line 41, in __call__
    return await handler(event, data)
           ^^^^^^^^^^^^^^^^^^^^^^^^^^
  File "/root/bot-bugalter/auto-reports-bot/venv/lib/python3.11/site-packages/aiogram/dispatcher/event/telegram.py", line 121, in trigger
    return await wrapped_inner(event, kwargs)
           ^^^^^^^^^^^^^^^^^^^^^^^^^^^^^^^^^^
  File "/root/bot-bugalter/auto-reports-bot/venv/lib/python3.11/site-packages/aiogram/dispatcher/event/handler.py", line 43, in call
    return await wrapped()
           ^^^^^^^^^^^^^^^
  File "/root/bot-bugalter/auto-reports-bot/venv/lib/python3.11/site-packages/aiogram/dispatcher/dispatcher.py", line 276, in _listen_update
    return await self.propagate_event(update_type=update_type, event=event, **kwargs)
           ^^^^^^^^^^^^^^^^^^^^^^^^^^^^^^^^^^^^^^^^^^^^^^^^^^^^^^^^^^^^^^^^^^^^^^^^^^
  File "/root/bot-bugalter/auto-reports-bot/venv/lib/python3.11/site-packages/aiogram/dispatcher/router.py", line 128, in propagate_event
    return await observer.wrap_outer_middleware(_wrapped, event=event, data=kwargs)
           ^^^^^^^^^^^^^^^^^^^^^^^^^^^^^^^^^^^^^^^^^^^^^^^^^^^^^^^^^^^^^^^^^^^^^^^^
  File "/root/bot-bugalter/auto-reports-bot/venv/lib/python3.11/site-packages/aiogram/dispatcher/router.py", line 123, in _wrapped
    return await self._propagate_event(
           ^^^^^^^^^^^^^^^^^^^^^^^^^^^^
  File "/root/bot-bugalter/auto-reports-bot/venv/lib/python3.11/site-packages/aiogram/dispatcher/router.py", line 148, in _propagate_event
    response = await observer.trigger(event, **kwargs)
               ^^^^^^^^^^^^^^^^^^^^^^^^^^^^^^^^^^^^^^^
  File "/root/bot-bugalter/auto-reports-bot/venv/lib/python3.11/site-packages/aiogram/dispatcher/event/telegram.py", line 121, in trigger
    return await wrapped_inner(event, kwargs)
           ^^^^^^^^^^^^^^^^^^^^^^^^^^^^^^^^^^
  File "/root/bot-bugalter/auto-reports-bot/venv/lib/python3.11/site-packages/aiogram/dispatcher/event/handler.py", line 43, in call
    return await wrapped()
           ^^^^^^^^^^^^^^^
  File "/root/bot-bugalter/auto-reports-bot/bot.py", line 26, in msg_handler
    report = await parse(msg)
             ^^^^^^^^^^^^^^^^
  File "/root/bot-bugalter/auto-reports-bot/modules/parser.py", line 129, in parse
    nickname=employees[0].username,
             ~~~~~~~~~^^^
IndexError: list index out of range
Cause exception while process update id=722185133 by bot id=6842489166
PermissionError: [Errno 1] Operation not permitted: 'tables/main_table.xlsx'
Traceback (most recent call last):
  File "/root/bot-bugalter/venv-ar/lib/python3.11/site-packages/aiogram/dispatcher/dispatcher.py", line 309, in _process_update
    response = await self.feed_update(bot, update, **kwargs)
               ^^^^^^^^^^^^^^^^^^^^^^^^^^^^^^^^^^^^^^^^^^^^^
  File "/root/bot-bugalter/venv-ar/lib/python3.11/site-packages/aiogram/dispatcher/dispatcher.py", line 158, in feed_update
    response = await self.update.wrap_outer_middleware(
               ^^^^^^^^^^^^^^^^^^^^^^^^^^^^^^^^^^^^^^^^
  File "/root/bot-bugalter/venv-ar/lib/python3.11/site-packages/aiogram/dispatcher/middlewares/error.py", line 25, in __call__
    return await handler(event, data)
           ^^^^^^^^^^^^^^^^^^^^^^^^^^
  File "/root/bot-bugalter/venv-ar/lib/python3.11/site-packages/aiogram/dispatcher/middlewares/user_context.py", line 27, in __call__
    return await handler(event, data)
           ^^^^^^^^^^^^^^^^^^^^^^^^^^
  File "/root/bot-bugalter/venv-ar/lib/python3.11/site-packages/aiogram/fsm/middleware.py", line 41, in __call__
    return await handler(event, data)
           ^^^^^^^^^^^^^^^^^^^^^^^^^^
  File "/root/bot-bugalter/venv-ar/lib/python3.11/site-packages/aiogram/dispatcher/event/telegram.py", line 121, in trigger
    return await wrapped_inner(event, kwargs)
           ^^^^^^^^^^^^^^^^^^^^^^^^^^^^^^^^^^
  File "/root/bot-bugalter/venv-ar/lib/python3.11/site-packages/aiogram/dispatcher/event/handler.py", line 43, in call
    return await wrapped()
           ^^^^^^^^^^^^^^^
  File "/root/bot-bugalter/venv-ar/lib/python3.11/site-packages/aiogram/dispatcher/dispatcher.py", line 276, in _listen_update
    return await self.propagate_event(update_type=update_type, event=event, **kwargs)
           ^^^^^^^^^^^^^^^^^^^^^^^^^^^^^^^^^^^^^^^^^^^^^^^^^^^^^^^^^^^^^^^^^^^^^^^^^^
  File "/root/bot-bugalter/venv-ar/lib/python3.11/site-packages/aiogram/dispatcher/router.py", line 128, in propagate_event
    return await observer.wrap_outer_middleware(_wrapped, event=event, data=kwargs)
           ^^^^^^^^^^^^^^^^^^^^^^^^^^^^^^^^^^^^^^^^^^^^^^^^^^^^^^^^^^^^^^^^^^^^^^^^
  File "/root/bot-bugalter/venv-ar/lib/python3.11/site-packages/aiogram/dispatcher/router.py", line 123, in _wrapped
    return await self._propagate_event(
           ^^^^^^^^^^^^^^^^^^^^^^^^^^^^
  File "/root/bot-bugalter/venv-ar/lib/python3.11/site-packages/aiogram/dispatcher/router.py", line 156, in _propagate_event
    response = await router.propagate_event(update_type=update_type, event=event, **kwargs)
               ^^^^^^^^^^^^^^^^^^^^^^^^^^^^^^^^^^^^^^^^^^^^^^^^^^^^^^^^^^^^^^^^^^^^^^^^^^^^
  File "/root/bot-bugalter/venv-ar/lib/python3.11/site-packages/aiogram/dispatcher/router.py", line 128, in propagate_event
    return await observer.wrap_outer_middleware(_wrapped, event=event, data=kwargs)
           ^^^^^^^^^^^^^^^^^^^^^^^^^^^^^^^^^^^^^^^^^^^^^^^^^^^^^^^^^^^^^^^^^^^^^^^^
  File "/root/bot-bugalter/venv-ar/lib/python3.11/site-packages/aiogram/dispatcher/router.py", line 123, in _wrapped
    return await self._propagate_event(
           ^^^^^^^^^^^^^^^^^^^^^^^^^^^^
  File "/root/bot-bugalter/venv-ar/lib/python3.11/site-packages/aiogram/dispatcher/router.py", line 148, in _propagate_event
    response = await observer.trigger(event, **kwargs)
               ^^^^^^^^^^^^^^^^^^^^^^^^^^^^^^^^^^^^^^^
  File "/root/bot-bugalter/venv-ar/lib/python3.11/site-packages/aiogram/dispatcher/event/telegram.py", line 121, in trigger
    return await wrapped_inner(event, kwargs)
           ^^^^^^^^^^^^^^^^^^^^^^^^^^^^^^^^^^
  File "/root/bot-bugalter/venv-ar/lib/python3.11/site-packages/aiogram/dispatcher/event/handler.py", line 43, in call
    return await wrapped()
           ^^^^^^^^^^^^^^^
  File "/root/bot-bugalter/auto-reports-bot/routers/tables.py", line 41, in send_tables
    await gather_tables([f.strip() for f in filters])
  File "/root/bot-bugalter/auto-reports-bot/modules/utils.py", line 109, in gather_tables
    shutil.copy(
  File "/usr/lib/python3.11/shutil.py", line 432, in copy
    copymode(src, dst, follow_symlinks=follow_symlinks)
  File "/usr/lib/python3.11/shutil.py", line 313, in copymode
    chmod_func(dst, stat.S_IMODE(st.st_mode))
PermissionError: [Errno 1] Operation not permitted: 'tables/main_table.xlsx'
